Workbook

Sheet 사용안내
A1: 3개 기업 재무제표 비교분석기 (DART Open API 연동)
A3: 1. 데이터 출처
A4: - 금융감독원 전자공시시스템(DART) Open API (opendart.fss.or.kr)
A5: - 각 기업 최신 사업보고서(연간) 기준 연결재무제표(CFS, 연결 재무제표 미제출 시 별도(OFS))를 사용했습니다.
A6: - 배당 정보는 DART '배당에 관한 사항(alotMatter)' 공시를 사용했으며, 원 단위(백만원 -> 원 환산)로 표시했습니다.
A7: - '원본데이터' 시트 각 회사 블록 상단에 회사별 corp_code, 종목코드, 사업연도, 재무제표 구분을 표기했습니다.
A9: 2. 이 파일의 구성
A10: - 원본데이터 : DART에서 가져온 3개 기업 x 3개년 원본 재무제표/배당 수치
A11: - 비교분석 : 원본데이터를 참조하는 수식으로 수익성/안정성/성장성/배당 지표를 자동 계산, 3개 기업을 나란히 비교
A12: - 대시보드 : 매출액·영업이익·순이익 추이 및 수익성/안정성/배당성향 비교 차트, 최신연도 요약 스코어카드
A14: 3. 주의사항
A15: - 이 데이터는 스크립트 실행 시점(DART 최신 공시 기준)의 스냅샷입니다. 최신 공시가 갱신되면 다시 조회해야 합니다.
... A18: - 값은 원(KRW) 단위입니다.

Sheet 원본데이터
A1: 3개 기업 재무제표 원본 데이터 (단위: 원)
A3: ■ 한국전력 (한국전력공사)
A4: 출처: DART Open API, corp_code=00159193, 종목코드=015760, 사업연도=2025(사업보고서), 재무제표구분=CFS (연결), 배당: alotMatter 공시
A5: 항목 | B5: 2023 | C5: 2024 | D5: 2025
A6: 매출액 | B6: 88219461000000 | C6: 93398896000000 | D6: 97429346000000
A7: 매출원가 | B7: 89699527000000 | C7: 81964160000000 | D7: 80704812000000
A8: 매출총이익 | B8: =IFERROR(B6-B7,"N/A") | C8: =IFERROR(C6-C7,"N/A") | D8: =IFERROR(D6-D7,"N/A")
A9: 영업이익 | B9: -4541648000000 | C9: 8364710000000 | D9: 13490557000000
A10: 당기순이익 | B10: -4716144000000 | C10: 3621968000000 | D10: 8666656000000
A11: 유동자산 | B11: 29536215000000 | C11: 29255205000000 | D11: 30715388000000
A12: 재고자산 | B12: 8875615000000 | C12: 9769236000000 | D12: 10152724000000
A13: 유동부채 | B13: 61248421000000 | C13: 63968789000000 | D13: 67107317000000
A14: 자산총계 | B14: 239714965000000 | C14: 246807795000000 | D14: 254927457000000
A15: 부채총계 | B15: 202450215000000 | C15: 205444962000000 | D15: 205604513000000
A16: 자본총계 | B16: 37264750000000 | C16: 41362833000000 | D16: 49322944000000
A17: 현금배당금총액 | B17: N/A | C17: 136738000000 | D17: 989909000000
A19: ■ LG에너지솔루션 (LG에너지솔루션)
A20: 출처: DART Open API, corp_code=01515323, 종목코드=373220, 사업연도=2025(사업보고서), 재무제표구분=CFS (연결), 배당: alotMatter 공시
A21: 항목 | B21: 2023 | C21: 2024 | D21: 2025
A22: 매출액 | B22: 33745470000000 | C22: 25619585000000 | D22: 23671759000000
A23: 매출원가 | B23: 28802437000000 | C23: 22213605000000 | D23: 19439651000000
A24: 매출총이익 | B24: =IFERROR(B22-B23,"N/A") | C24: =IFERROR(C22-C23,"N/A") | D24: =IFERROR(D22-D23,"N/A")
A25: 영업이익 | B25: 2163234000000 | C25: 575387000000 | D25: 1346120000000
A26: 당기순이익 | B26: 1637985000000 | C26: 338602000000 | D26: 80803000000
A27: 유동자산 | B27: 17208396000000 | C27: 15327395000000 | D27: 18412127000000
A28: 재고자산 | B28: 5396336000000 | C28: 4552355000000 | D28: 4350407000000
A29: 유동부채 | B29: 10937185000000 | C29: 12054922000000 | D29: 16785357000000
A30: 자산총계 | B30: 45437144000000 | C30: 60306791000000 | D30: 67147953000000
A31: 부채총계 | B31: 21063635000000 | C31: 29340248000000 | D31: 37826277000000
A32: 자본총계 | B32: 24373509000000 | C32: 30966543000000 | D32: 29321676000000
A33: 현금배당금총액 | B33: N/A | C33: N/A | D33: N/A
A35: ■ HD현대 (HD현대)
A36: 출처: DART Open API, corp_code=01205709, 종목코드=267250, 사업연도=2025(사업보고서), 재무제표구분=CFS (연결), 배당: alotMatter 공시
A37: 항목 | B37: 2023 | C37: 2024 | D37: 2025
A38: 매출액 | B38: 61331302785000 | C38: 67765626088000 | D38: 71259438270000
A39: 매출원가 | B39: 56366042540000 | C39: 61338721114000 | D39: 61203798281000
A40: 매출총이익 | B40: =IFERROR(B38-B39,"N/A") | C40: =IFERROR(C38-C39,"N/A") | D40: =IFERROR(D38-D39,"N/A")
A41: 영업이익 | B41: 2031563587000 | C41: 2983162778000 | D41: 6099636253000
A42: 당기순이익 | B42: 785832206000 | C42: 1930179481000 | D42: 3675482625000
A43: 유동자산 | B43: 32083110520000 | C43: 35592849734000 | D43: 39632675115000
...

Sheet 비교분석
A1: 3개 기업 재무비율 비교분석
A3: [ 수익성 지표 ]
A4: 매출총이익률 | B4: 2023 | C4: 2024 | D4: 2025
A5: 한국전력 | B5: =IFERROR('원본데이터'!B8/'원본데이터'!B6,"-") | C5: =IFERROR('원본데이터'!C8/'원본데이터'!C6,"-") | D5: =IFERROR('원본데이터'!D8/'원본데이터'!D6,"-")
A6: LG에너지솔루션 | B6: =IFERROR('원본데이터'!B24/'원본데이터'!B22,"-") | C6: =IFERROR('원본데이터'!C24/'원본데이터'!C22,"-") | D6: =IFERROR('원본데이터'!D24/'원본데이터'!D22,"-")
A7: HD현대 | B7: =IFERROR('원본데이터'!B40/'원본데이터'!B38,"-") | C7: =IFERROR('원본데이터'!C40/'원본데이터'!C38,"-") | D7: =IFERROR('원본데이터'!D40/'원본데이터'!D38,"-")
A9: 영업이익률 | B9: 2023 | C9: 2024 | D9: 2025
A10: 한국전력 | B10: =IFERROR('원본데이터'!B9/'원본데이터'!B6,"-") | C10: =IFERROR('원본데이터'!C9/'원본데이터'!C6,"-") | D10: =IFERROR('원본데이터'!D9/'원본데이터'!D6,"-")
A11: LG에너지솔루션 | B11: =IFERROR('원본데이터'!B25/'원본데이터'!B22,"-") | C11: =IFERROR('원본데이터'!C25/'원본데이터'!C22,"-") | D11: =IFERROR('원본데이터'!D25/'원본데이터'!D22,"-")
A12: HD현대 | B12: =IFERROR('원본데이터'!B41/'원본데이터'!B38,"-") | C12: =IFERROR('원본데이터'!C41/'원본데이터'!C38,"-") | D12: =IFERROR('원본데이터'!D41/'원본데이터'!D38,"-")
A14: 순이익률 | B14: 2023 | C14: 2024 | D14: 2025
A15: 한국전력 | B15: =IFERROR('원본데이터'!B10/'원본데이터'!B6,"-") | C15: =IFERROR('원본데이터'!C10/'원본데이터'!C6,"-") | D15: =IFERROR('원본데이터'!D10/'원본데이터'!D6,"-")
A16: LG에너지솔루션 | B16: =IFERROR('원본데이터'!B26/'원본데이터'!B22,"-") | C16: =IFERROR('원본데이터'!C26/'원본데이터'!C22,"-") | D16: =IFERROR('원본데이터'!D26/'원본데이터'!D22,"-")
A17: HD현대 | B17: =IFERROR('원본데이터'!B42/'원본데이터'!B38,"-") | C17: =IFERROR('원본데이터'!C42/'원본데이터'!C38,"-") | D17: =IFERROR('원본데이터'!D42/'원본데이터'!D38,"-")
A19: ROA (총자산순이익률) | B19: 2023 | C19: 2024 | D19: 2025
A20: 한국전력 | B20: =IFERROR('원본데이터'!B10/'원본데이터'!B14,"-") | C20: =IFERROR('원본데이터'!C10/'원본데이터'!C14,"-") | D20: =IFERROR('원본데이터'!D10/'원본데이터'!D14,"-")
A21: LG에너지솔루션 | B21: =IFERROR('원본데이터'!B26/'원본데이터'!B30,"-") | C21: =IFERROR('원본데이터'!C26/'원본데이터'!C30,"-") | D21: =IFERROR('원본데이터'!D26/'원본데이터'!D30,"-")
A22: HD현대 | B22: =IFERROR('원본데이터'!B42/'원본데이터'!B46,"-") | C22: =IFERROR('원본데이터'!C42/'원본데이터'!C46,"-") | D22: =IFERROR('원본데이터'!D42/'원본데이터'!D46,"-")
A24: ROE (자기자본순이익률) | B24: 2023 | C24: 2024 | D24: 2025
A25: 한국전력 | B25: =IFERROR('원본데이터'!B10/'원본데이터'!B16,"-") | C25: =IFERROR('원본데이터'!C10/'원본데이터'!C16,"-") | D25: =IFERROR('원본데이터'!D10/'원본데이터'!D16,"-")
A26: LG에너지솔루션 | B26: =IFERROR('원본데이터'!B26/'원본데이터'!B32,"-") | C26: =IFERROR('원본데이터'!C26/'원본데이터'!C32,"-") | D26: =IFERROR('원본데이터'!D26/'원본데이터'!D32,"-")
A27: HD현대 | B27: =IFERROR('원본데이터'!B42/'원본데이터'!B48,"-") | C27: =IFERROR('원본데이터'!C42/'원본데이터'!C48,"-") | D27: =IFERROR('원본데이터'!D42/'원본데이터'!D48,"-")
A29: [ 안정성 지표 ]
A30: 부채비율 | B30: 2023 | C30: 2024 | D30: 2025
A31: 한국전력 | B31: =IFERROR('원본데이터'!B15/'원본데이터'!B16,"-") | C31: =IFERROR('원본데이터'!C15/'원본데이터'!C16,"-") | D31: =IFERROR('원본데이터'!D15/'원본데이터'!D16,"-")
A32: LG에너지솔루션 | B32: =IFERROR('원본데이터'!B31/'원본데이터'!B32,"-") | C32: =IFERROR('원본데이터'!C31/'원본데이터'!C32,"-") | D32: =IFERROR('원본데이터'!D31/'원본데이터'!D32,"-")
A33: HD현대 | B33: =IFERROR('원본데이터'!B47/'원본데이터'!B48,"-") | C33: =IFERROR('원본데이터'!C47/'원본데이터'!C48,"-") | D33: =IFERROR('원본데이터'!D47/'원본데이터'!D48,"-")
A35: 유동비율 | B35: 2023 | C35: 2024 | D35: 2025
A36: 한국전력 | B36: =IFERROR('원본데이터'!B11/'원본데이터'!B13,"-") | C36: =IFERROR('원본데이터'!C11/'원본데이터'!C13,"-") | D36: =IFERROR('원본데이터'!D11/'원본데이터'!D13,"-")
A37: LG에너지솔루션 | B37: =IFERROR('원본데이터'!B27/'원본데이터'!B29,"-") | C37: =IFERROR('원본데이터'!C27/'원본데이터'!C29,"-") | D37: =IFERROR('원본데이터'!D27/'원본데이터'!D29,"-")
A38: HD현대 | B38: =IFERROR('원본데이터'!B43/'원본데이터'!B45,"-") | C38: =IFERROR('원본데이터'!C43/'원본데이터'!C45,"-") | D38: =IFERROR('원본데이터'!D43/'원본데이터'!D45,"-")
A40: 자기자본비율 | B40: 2023 | C40: 2024 | D40: 2025
A41: 한국전력 | B41: =IFERROR('원본데이터'!B16/'원본데이터'!B14,"-") | C41: =IFERROR('원본데이터'!C16/'원본데이터'!C14,"-") | D41: =IFERROR('원본데이터'!D16/'원본데이터'!D14,"-")
A42: LG에너지솔루션 | B42: =IFERROR('원본데이터'!B32/'원본데이터'!B30,"-") | C42: =IFERROR('원본데이터'!C32/'원본데이터'!C30,"-") | D42: =IFERROR('원본데이터'!D32/'원본데이터'!D30,"-")
A43: HD현대 | B43: =IFERROR('원본데이터'!B48/'원본데이터'!B46,"-") | C43: =IFERROR('원본데이터'!C48/'원본데이터'!C46,"-") | D43: =IFERROR('원본데이터'!D48/'원본데이터'!D46,"-")
A45: [ 배당 지표 ]
A46: 배당성향 | B46: 2023 | C46: 2024 | D46: 2025
A47: 한국전력 | B47: =IFERROR('원본데이터'!B17/'원본데이터'!B10,"-") | C47: =IFERROR('원본데이터'!C17/'원본데이터'!C10,"-") | D47: =IFERROR('원본데이터'!D17/'원본데이터'!D10,"-")
A48: LG에너지솔루션 | B48: =IFERROR('원본데이터'!B33/'원본데이터'!B26,"-") | C48: =IFERROR('원본데이터'!C33/'원본데이터'!C26,"-") | D48: =IFERROR('원본데이터'!D33/'원본데이터'!D26,"-")
A49: HD현대 | B49: =IFERROR('원본데이터'!B49/'원본데이터'!B42,"-") | C49: =IFERROR('원본데이터'!C49/'원본데이터'!C42,"-") | D49: =IFERROR('원본데이터'!D49/'원본데이터'!D42,"-")
...

Sheet 대시보드
A1: 3개 기업 재무비교 대시보드 (한국전력 / LG에너지솔루션 / HD현대)
A2: 기준: 2023~2025 사업보고서 (연결재무제표 기준, DART Open API)
A55: ■ 2025년 요약 스코어카드
A56: 회사명 | B56: 영업이익률 | C56: 순이익률 | D56: ROE (자기자본순이익률) | E56: 부채비율 | F56: 유동비율 | G56: 배당성향 | H56: 매출액증가율
A57: 한국전력 | B57: ='비교분석'!D10 | C57: ='비교분석'!D15 | D57: ='비교분석'!D25 | E57: ='비교분석'!D31 | F57: ='비교분석'!D36 | G57: ='비교분석'!D47 | H57: ='비교분석'!D53
A58: LG에너지솔루션 | B58: ='비교분석'!D11 | C58: ='비교분석'!D16 | D58: ='비교분석'!D26 | E58: ='비교분석'!D32 | F58: ='비교분석'!D37 | G58: ='비교분석'!D48 | H58: ='비교분석'!D54
A59: HD현대 | B59: ='비교분석'!D12 | C59: ='비교분석'!D17 | D59: ='비교분석'!D27 | E59: ='비교분석'!D33 | F59: ='비교분석'!D38 | G59: ='비교분석'!D49 | H59: ='비교분석'!D55
A61: ※ 배당성향이 '-'로 표시된 경우 해당 연도 배당을 실시하지 않았거나 DART 공시에 항목이 없는 경우입니다 (예: LG에너지솔루션).
