Workbook

Sheet 사용안내
A1: 3개 기업 재무제표 비교분석기 + 배당소득 분리과세 대상 판정
A3: 1. 데이터 출처
A4: - 금융감독원 전자공시시스템(DART) Open API (opendart.fss.or.kr)
A5: - 재무제표: 각 기업 최신 사업보고서(연간) 기준 연결재무제표(CFS, 미제출 시 별도 OFS)
A6: - 배당: DART '배당에 관한 사항(alotMatter)' 공시. 현금배당금총액과 기업이 직접 공시한 (연결)현금배당성향(%)을 함께 사용
A8: 2. 이 파일의 구성
A9: - 원본데이터 : 3개 기업 x 3개년 원본 재무제표 수치
A10: - 비교분석 : 수익성/안정성/성장성 지표 자동 계산 비교
A11: - 대시보드 : 추이 차트 및 최신연도 요약 스코어카드
A12: - 분리과세판정 : 2026년 시행 예정 배당소득 분리과세 특례의 '고배당기업' 요건 충족 여부 추정
A14: 3. 분리과세판정 시트 관련 중요 안내
A15: - 이 시트는 조세특례제한법 제104조의27(고배당기업 주식 배당소득에 대한 과세특례, 2025.12.23. 신설,
... A19: 분리과세를 신청할 수 있는지 여부입니다.

Sheet 원본데이터
A1: 3개 기업 재무제표 원본 데이터 (단위: 원)
A3: ■ 한국전력 (한국전력공사)
A4: 출처: DART Open API, corp_code=00159193, 종목코드=015760, 사업연도=2025(사업보고서), 재무제표구분=CFS(연결)
A5: 항목 | B5: 2023 | C5: 2024 | D5: 2025
A6: 매출액 | B6: 88219461000000 | C6: 93398896000000 | D6: 97429346000000
A7: 매출원가 | B7: 89699527000000 | C7: 81964160000000 | D7: 80704812000000
A8: 매출총이익 | B8: =IFERROR(B6-B7,"N/A") -> -1480066000000 | C8: =IFERROR(C6-C7,"N/A") -> 11434736000000 | D8: =IFERROR(D6-D7,"N/A") -> 16724534000000
A9: 영업이익 | B9: -4541648000000 | C9: 8364710000000 | D9: 13490557000000
A10: 당기순이익 | B10: -4716144000000 | C10: 3621968000000 | D10: 8666656000000
A11: 유동자산 | B11: 29536215000000 | C11: 29255205000000 | D11: 30715388000000
A12: 재고자산 | B12: 8875615000000 | C12: 9769236000000 | D12: 10152724000000
A13: 유동부채 | B13: 61248421000000 | C13: 63968789000000 | D13: 67107317000000
A14: 자산총계 | B14: 239714965000000 | C14: 246807795000000 | D14: 254927457000000
A15: 부채총계 | B15: 202450215000000 | C15: 205444962000000 | D15: 205604513000000
A16: 자본총계 | B16: 37264750000000 | C16: 41362833000000 | D16: 49322944000000
A18: ■ 삼성전자 (삼성전자)
A19: 출처: DART Open API, corp_code=00126380, 종목코드=005930, 사업연도=2025(사업보고서), 재무제표구분=CFS(연결)
A20: 항목 | B20: 2023 | C20: 2024 | D20: 2025
A21: 매출액 | B21: 258935494000000 | C21: 300870903000000 | D21: 333605938000000
A22: 매출원가 | B22: 180388580000000 | C22: 186562268000000 | D22: 202235513000000
A23: 매출총이익 | B23: =IFERROR(B21-B22,"N/A") -> 78546914000000 | C23: =IFERROR(C21-C22,"N/A") -> 114308635000000 | D23: =IFERROR(D21-D22,"N/A") -> 131370425000000
A24: 영업이익 | B24: 6566976000000 | C24: 32725961000000 | D24: 43601051000000
A25: 당기순이익 | B25: 15487100000000 | C25: 34451351000000 | D25: 45206805000000
A26: 유동자산 | B26: 195936557000000 | C26: 227062266000000 | D26: 247684612000000
A27: 재고자산 | B27: 51625874000000 | C27: 51754865000000 | D27: 52636828000000
A28: 유동부채 | B28: 75719452000000 | C28: 93326299000000 | D28: 106411348000000
A29: 자산총계 | B29: 455905980000000 | C29: 514531948000000 | D29: 566942110000000
A30: 부채총계 | B30: 92228115000000 | C30: 112339878000000 | D30: 130621773000000
A31: 자본총계 | B31: 363677865000000 | C31: 402192070000000 | D31: 436320337000000
A33: ■ SK하이닉스 (SK하이닉스)
A34: 출처: DART Open API, corp_code=00164779, 종목코드=000660, 사업연도=2025(사업보고서), 재무제표구분=CFS(연결)
A35: 항목 | B35: 2023 | C35: 2024 | D35: 2025
A36: 매출액 | B36: 32765719000000 | C36: 66192960000000 | D36: 97146675000000
A37: 매출원가 | B37: 33299167000000 | C37: 34364814000000 | D37: 38455885000000
A38: 매출총이익 | B38: =IFERROR(B36-B37,"N/A") -> -533448000000 | C38: =IFERROR(C36-C37,"N/A") -> 31828146000000 | D38: =IFERROR(D36-D37,"N/A") -> 58690790000000
A39: 영업이익 | B39: -7730313000000 | C39: 23467319000000 | D39: 47206319000000
A40: 당기순이익 | B40: -9137547000000 | C40: 19796902000000 | D40: 42947902000000
A41: 유동자산 | B41: 30468100000000 | C41: 42278887000000 | D41: 69458073000000
A42: 재고자산 | B42: 13480659000000 | C42: 13313937000000 | D42: 14289390000000
A43: 유동부채 | B43: 21007810000000 | C43: 24965444000000 | D43: 37378999000000
...

Sheet 비교분석
A1: 3개 기업 재무비율 비교분석
A3: [ 수익성 지표 ]
A4: 매출총이익률 | B4: 2023 | C4: 2024 | D4: 2025
A5: 한국전력 | B5: =IFERROR(원본데이터!B8/원본데이터!B6,"-") -> -0.016777092 | C5: =IFERROR(원본데이터!C8/원본데이터!C6,"-") -> 0.12242903 | D5: =IFERROR(원본데이터!D8/원본데이터!D6,"-") -> 0.17165808
A6: 삼성전자 | B6: =IFERROR(원본데이터!B23/원본데이터!B21,"-") -> 0.30334549 | C6: =IFERROR(원본데이터!C23/원본데이터!C21,"-") -> 0.37992585 | D6: =IFERROR(원본데이터!D23/원본데이터!D21,"-") -> 0.39378923
A7: SK하이닉스 | B7: =IFERROR(원본데이터!B38/원본데이터!B36,"-") -> -0.016280674 | C7: =IFERROR(원본데이터!C38/원본데이터!C36,"-") -> 0.48083884 | D7: =IFERROR(원본데이터!D38/원본데이터!D36,"-") -> 0.60414615
A9: 영업이익률 | B9: 2023 | C9: 2024 | D9: 2025
A10: 한국전력 | B10: =IFERROR(원본데이터!B9/원본데이터!B6,"-") -> -0.051481249 | C10: =IFERROR(원본데이터!C9/원본데이터!C6,"-") -> 0.089558982 | D10: =IFERROR(원본데이터!D9/원본데이터!D6,"-") -> 0.13846503
A11: 삼성전자 | B11: =IFERROR(원본데이터!B24/원본데이터!B21,"-") -> 0.025361436 | C11: =IFERROR(원본데이터!C24/원본데이터!C21,"-") -> 0.10877077 | D11: =IFERROR(원본데이터!D24/원본데이터!D21,"-") -> 0.13069627
A12: SK하이닉스 | B12: =IFERROR(원본데이터!B39/원본데이터!B36,"-") -> -0.23592685 | C12: =IFERROR(원본데이터!C39/원본데이터!C36,"-") -> 0.35452893 | D12: =IFERROR(원본데이터!D39/원본데이터!D36,"-") -> 0.4859283
A14: 순이익률 | B14: 2023 | C14: 2024 | D14: 2025
A15: 한국전력 | B15: =IFERROR(원본데이터!B10/원본데이터!B6,"-") -> -0.053459225 | C15: =IFERROR(원본데이터!C10/원본데이터!C6,"-") -> 0.038779559 | D15: =IFERROR(원본데이터!D10/원본데이터!D6,"-") -> 0.08895324
A16: 삼성전자 | B16: =IFERROR(원본데이터!B25/원본데이터!B21,"-") -> 0.059810649 | C16: =IFERROR(원본데이터!C25/원본데이터!C21,"-") -> 0.11450543 | D16: =IFERROR(원본데이터!D25/원본데이터!D21,"-") -> 0.13550959
A17: SK하이닉스 | B17: =IFERROR(원본데이터!B40/원본데이터!B36,"-") -> -0.27887522 | C17: =IFERROR(원본데이터!C40/원본데이터!C36,"-") -> 0.29907866 | D17: =IFERROR(원본데이터!D40/원본데이터!D36,"-") -> 0.44209338
A19: ROA (총자산순이익률) | B19: 2023 | C19: 2024 | D19: 2025
A20: 한국전력 | B20: =IFERROR(원본데이터!B10/원본데이터!B14,"-") -> -0.019673966 | C20: =IFERROR(원본데이터!C10/원본데이터!C14,"-") -> 0.014675258 | D20: =IFERROR(원본데이터!D10/원본데이터!D14,"-") -> 0.033996558
A21: 삼성전자 | B21: =IFERROR(원본데이터!B25/원본데이터!B29,"-") -> 0.033969943 | C21: =IFERROR(원본데이터!C25/원본데이터!C29,"-") -> 0.06695668 | D21: =IFERROR(원본데이터!D25/원본데이터!D29,"-") -> 0.079737956
A22: SK하이닉스 | B22: =IFERROR(원본데이터!B40/원본데이터!B44,"-") -> -0.091074773 | C22: =IFERROR(원본데이터!C40/원본데이터!C44,"-") -> 0.16517348 | D22: =IFERROR(원본데이터!D40/원본데이터!D44,"-") -> 0.24387299
A24: ROE (자기자본순이익률) | B24: 2023 | C24: 2024 | D24: 2025
A25: 한국전력 | B25: =IFERROR(원본데이터!B10/원본데이터!B16,"-") -> -0.12655778 | C25: =IFERROR(원본데이터!C10/원본데이터!C16,"-") -> 0.087565762 | D25: =IFERROR(원본데이터!D10/원본데이터!D16,"-") -> 0.17571246
A26: 삼성전자 | B26: =IFERROR(원본데이터!B25/원본데이터!B31,"-") -> 0.042584665 | C26: =IFERROR(원본데이터!C25/원본데이터!C31,"-") -> 0.085658951 | D26: =IFERROR(원본데이터!D25/원본데이터!D31,"-") -> 0.10360921
A27: SK하이닉스 | B27: =IFERROR(원본데이터!B40/원본데이터!B46,"-") -> -0.17078329 | C27: =IFERROR(원본데이터!C40/원본데이터!C46,"-") -> 0.2678308 | D27: =IFERROR(원본데이터!D40/원본데이터!D46,"-") -> 0.35592159
A29: [ 안정성 지표 ]
A30: 부채비율 | B30: 2023 | C30: 2024 | D30: 2025
A31: 한국전력 | B31: =IFERROR(원본데이터!B15/원본데이터!B16,"-") -> 5.4327539 | C31: =IFERROR(원본데이터!C15/원본데이터!C16,"-") -> 4.9668977 | D31: =IFERROR(원본데이터!D15/원본데이터!D16,"-") -> 4.1685369
A32: 삼성전자 | B32: =IFERROR(원본데이터!B30/원본데이터!B31,"-") -> 0.25359837 | C32: =IFERROR(원본데이터!C30/원본데이터!C31,"-") -> 0.27931898 | D32: =IFERROR(원본데이터!D30/원본데이터!D31,"-") -> 0.29937127
A33: SK하이닉스 | B33: =IFERROR(원본데이터!B45/원본데이터!B46,"-") -> 0.87519868 | C33: =IFERROR(원본데이터!C45/원본데이터!C46,"-") -> 0.62151211 | D33: =IFERROR(원본데이터!D45/원본데이터!D46,"-") -> 0.45945472
A35: 유동비율 | B35: 2023 | C35: 2024 | D35: 2025
A36: 한국전력 | B36: =IFERROR(원본데이터!B11/원본데이터!B13,"-") -> 0.48223635 | C36: =IFERROR(원본데이터!C11/원본데이터!C13,"-") -> 0.45733561 | D36: =IFERROR(원본데이터!D11/원본데이터!D13,"-") -> 0.4577055
A37: 삼성전자 | B37: =IFERROR(원본데이터!B26/원본데이터!B28,"-") -> 2.5876648 | C37: =IFERROR(원본데이터!C26/원본데이터!C28,"-") -> 2.4329934 | D37: =IFERROR(원본데이터!D26/원본데이터!D28,"-") -> 2.3276146
A38: SK하이닉스 | B38: =IFERROR(원본데이터!B41/원본데이터!B43,"-") -> 1.4503225 | C38: =IFERROR(원본데이터!C41/원본데이터!C43,"-") -> 1.6934963 | D38: =IFERROR(원본데이터!D41/원본데이터!D43,"-") -> 1.8582112
A40: 자기자본비율 | B40: 2023 | C40: 2024 | D40: 2025
A41: 한국전력 | B41: =IFERROR(원본데이터!B16/원본데이터!B14,"-") -> 0.15545442 | C41: =IFERROR(원본데이터!C16/원본데이터!C14,"-") -> 0.16759127 | D41: =IFERROR(원본데이터!D16/원본데이터!D14,"-") -> 0.19347835
A42: 삼성전자 | B42: =IFERROR(원본데이터!B31/원본데이터!B29,"-") -> 0.79770365 | C42: =IFERROR(원본데이터!C31/원본데이터!C29,"-") -> 0.78166588 | D42: =IFERROR(원본데이터!D31/원본데이터!D29,"-") -> 0.76960298
A43: SK하이닉스 | B43: =IFERROR(원본데이터!B46/원본데이터!B44,"-") -> 0.53327683 | C43: =IFERROR(원본데이터!C46/원본데이터!C44,"-") -> 0.61670832 | D43: =IFERROR(원본데이터!D46/원본데이터!D44,"-") -> 0.68518741
A45: [ 성장성 지표 (전년 대비 증가율) ]
A46: 매출액증가율 | B46: 2023 | C46: 2024 | D46: 2025
A47: 한국전력 | B47: N/A | C47: =IFERROR((원본데이터!C6-원본데이터!B6)/원본데이터!B6,"-") -> 0.058710799 | D47: =IFERROR((원본데이터!D6-원본데이터!C6)/원본데이터!C6,"-") -> 0.04315308
A48: 삼성전자 | B48: N/A | C48: =IFERROR((원본데이터!C21-원본데이터!B21)/원본데이터!B21,"-") -> 0.16195311 | D48: =IFERROR((원본데이터!D21-원본데이터!C21)/원본데이터!C21,"-") -> 0.10880093
A49: SK하이닉스 | B49: N/A | C49: =IFERROR((원본데이터!C36-원본데이터!B36)/원본데이터!B36,"-") -> 1.0201895 | D49: =IFERROR((원본데이터!D36-원본데이터!C36)/원본데이터!C36,"-") -> 0.46762851
...

Sheet 대시보드
A1: 3개 기업 재무비교 대시보드 (한국전력 / 삼성전자 / SK하이닉스)
A2: 기준: 2023~2025 사업보고서 (연결재무제표 기준, DART Open API)
A55: ■ 2025년 요약 스코어카드
A56: 회사명 | B56: 영업이익률 | C56: 순이익률 | D56: ROE (자기자본순이익률) | E56: 부채비율 | F56: 유동비율 | G56: 매출액증가율
A57: 한국전력 | B57: =비교분석!D10 -> 0.13846503 | C57: =비교분석!D15 -> 0.08895324 | D57: =비교분석!D25 -> 0.17571246 | E57: =비교분석!D31 -> 4.1685369 | F57: =비교분석!D36 -> 0.4577055 | G57: =비교분석!D47 -> 0.04315308
A58: 삼성전자 | B58: =비교분석!D11 -> 0.13069627 | C58: =비교분석!D16 -> 0.13550959 | D58: =비교분석!D26 -> 0.10360921 | E58: =비교분석!D32 -> 0.29937127 | F58: =비교분석!D37 -> 2.3276146 | G58: =비교분석!D48 -> 0.10880093
A59: SK하이닉스 | B59: =비교분석!D12 -> 0.4859283 | C59: =비교분석!D17 -> 0.44209338 | D59: =비교분석!D27 -> 0.35592159 | E59: =비교분석!D33 -> 0.45945472 | F59: =비교분석!D38 -> 1.8582112 | G59: =비교분석!D49 -> 0.46762851

Sheet 분리과세판정
A1: 배당소득 분리과세 대상(고배당기업) 요건 판정
A2: 조세특례제한법 제104조의27(고배당기업 주식 배당소득에 대한 과세특례, 2025.12.23. 신설) · 2026.1.1. 이후 지급 배당분부터 2028년까지 한시 적용
A3: ⚠ 주의: 이 판정은 조세특례제한법 제104조의27 조문(국가법령정보센터, 2025.12.23. 신설)을 근거로 구성했으나, 시행령 세부사항은 반영하지 못했습니다.
A4: - 요건(법조문): ① 직전 사업연도 배당소득이 2024사업연도보다 비감소, AND ② 직전 사업연도 배당성향 40% 이상 OR (배당성향 25% 이상 AND 전전사업연도 대비 배당금 10% 이상 증가)
A5: - 배당성향은 각 기업이 DART에 직접 공시한 (연결)현금배당성향(%)을 사용합니다 (원본데이터 시트의 자체 계산 순이익 기준과 소수 오차 있을 수 있음).
A6: - 코넥스 상장·투자회사 여부, 펀드/리츠/SPC 등 간접투자 제외 요건, 기업의 자체 요건 공시 여부는 확인하지 않았습니다.
A7: - 세율: 2천만원 이하 14%, 2천만원초과~3억원 20%(누진), 3억원초과~50억원 25%(누진), 50억원초과 30%(누진) — 초안 발표 당시(35% 3단계)와 실제 신설 조문의 세율이 다르므로 확정 조문 기준으로 표기.
A8: - 최종 판단은 국세청·기획재정부 공식 발표 또는 세무전문가 확인 후 하시기 바랍니다.
A10: ■ 요약 판정 결과 (2025 사업연도 기준)
A12: 한국전력 | B12: =E24 -> 요건 미충족 (추정)
A13: 삼성전자 | B13: =E34 -> 분리과세 대상 요건 충족 (추정)
A14: SK하이닉스 | B14: =E44 -> 요건 미충족 (추정)
A16: ■ 한국전력 (한국전력공사)
A17: 출처: DART alotMatter 공시 (접수번호 20260317000686, 20250318000747)
A18: 항목 | B18: 2022 | C18: 2023 | D18: 2024 | E18: 2025
A19: 현금배당금총액(원) | B19: N/A | C19: N/A | D19: 136738000000 | E19: 989909000000
A20: (연결)현금배당성향 [DART 공시] | B20: N/A | C20: N/A | D20: 0.039 | E20: 0.116
A21: ① 직전사업연도 배당, 2024사업연도 대비 비감소 | E21: =IF(OR(NOT(ISNUMBER(E19)),NOT(ISNUMBER(D19))),"판단불가",IF(E19>=D19,"충족","미충족")) -> 충족
A22: 전전사업연도 대비 증가율 | E22: =IFERROR(E19/D19-1,"-") -> 6.2394579
A23: ② 배당성향 40%+ 또는 (25%+ 및 전전사업연도 대비 10%+ 증가) | E23: =IF(NOT(ISNUMBER(E20)),"판단불가",IF(E20>=0.4,"충족(40%+)",IF(AND(E20>=0.25,ISNUMBER(E22),E22>=0.1),"충족(25%+ 및 전전사업연도대비10%+증가)","미충족"))) -> 미충족
A24: ▶ 최종 판정 (①AND②, 추정) | E24: =IF(OR(E21="판단불가",E23="판단불가"),"판단보류(자료부족, 공시 확인 필요)",IF(AND(E21="충족",LEFT(E23,2)="충족"),"분리과세 대상 요건 충족 (추정)","요건 미충족 (추정)")) -> 요건 미충족 (추정)
A26: ■ 삼성전자 (삼성전자)
A27: 출처: DART alotMatter 공시 (접수번호 20260310002820, 20250311001085)
A28: 항목 | B28: 2022 | C28: 2023 | D28: 2024 | E28: 2025
A29: 현금배당금총액(원) | B29: 9809438000000 | C29: 9809438000000 | D29: 9810767000000 | E29: 11107906000000
A30: (연결)현금배당성향 [DART 공시] | B30: 0.179 | C30: 0.678 | D30: 0.292 | E30: 0.251
A31: ① 직전사업연도 배당, 2024사업연도 대비 비감소 | E31: =IF(OR(NOT(ISNUMBER(E29)),NOT(ISNUMBER(D29))),"판단불가",IF(E29>=D29,"충족","미충족")) -> 충족
A32: 전전사업연도 대비 증가율 | E32: =IFERROR(E29/D29-1,"-") -> 0.13221586
A33: ② 배당성향 40%+ 또는 (25%+ 및 전전사업연도 대비 10%+ 증가) | E33: =IF(NOT(ISNUMBER(E30)),"판단불가",IF(E30>=0.4,"충족(40%+)",IF(AND(E30>=0.25,ISNUMBER(E32),E32>=0.1),"충족(25%+ 및 전전사업연도대비10%+증가)","미충족"))) -> 충족(25%+ 및 전전사업연도대비10%+증가)
A34: ▶ 최종 판정 (①AND②, 추정) | E34: =IF(OR(E31="판단불가",E33="판단불가"),"판단보류(자료부족, 공시 확인 필요)",IF(AND(E31="충족",LEFT(E33,2)="충족"),"분리과세 대상 요건 충족 (추정)","요건 미충족 (추정)")) -> 분리과세 대상 요건 충족 (추정)
A36: ■ SK하이닉스 (SK하이닉스)
A37: 출처: DART alotMatter 공시 (접수번호 20260317000635, 20250319000665)
A38: 항목 | B38: 2022 | C38: 2023 | D38: 2024 | E38: 2025
A39: 현금배당금총액(원) | B39: 825181000000 | C39: 825721000000 | D39: 1520090000000 | E39: 2095133000000
A40: (연결)현금배당성향 [DART 공시] | B40: 0.37 | C40: N/A | D40: 0.077 | E40: 0.049
A41: ① 직전사업연도 배당, 2024사업연도 대비 비감소 | E41: =IF(OR(NOT(ISNUMBER(E39)),NOT(ISNUMBER(D39))),"판단불가",IF(E39>=D39,"충족","미충족")) -> 충족
A42: 전전사업연도 대비 증가율 | E42: =IFERROR(E39/D39-1,"-") -> 0.37829536
A43: ② 배당성향 40%+ 또는 (25%+ 및 전전사업연도 대비 10%+ 증가) | E43: =IF(NOT(ISNUMBER(E40)),"판단불가",IF(E40>=0.4,"충족(40%+)",IF(AND(E40>=0.25,ISNUMBER(E42),E42>=0.1),"충족(25%+ 및 전전사업연도대비10%+증가)","미충족"))) -> 미충족
A44: ▶ 최종 판정 (①AND②, 추정) | E44: =IF(OR(E41="판단불가",E43="판단불가"),"판단보류(자료부족, 공시 확인 필요)",IF(AND(E41="충족",LEFT(E43,2)="충족"),"분리과세 대상 요건 충족 (추정)","요건 미충족 (추정)")) -> 요건 미충족 (추정)
